Workbook
Name CU?: 'Waterfall (10-yr-S1)'!$A$6
Name Equity_Share_GP: 'Waterfall (10-yr-S1)'!$C$9
Name Equity_Share_LP: 'Waterfall (10-yr-S1)'!$C$10
Name Preferred_Return: 'Waterfall (10-yr-S1)'!$E$15
Name Total_Equity: 'Waterfall (10-yr-S1)'!$D$11
Name CU?: 'Waterfall (5-yr-S1)'!$A$6
Name Equity_Share_GP: 'Waterfall (5-yr-S1)'!$C$9
Name Equity_Share_LP: 'Waterfall (5-yr-S1)'!$C$10
Name Preferred_Return: 'Waterfall (5-yr-S1)'!$E$15
Name Total_Equity: 'Waterfall (5-yr-S1)'!$D$11

Sheet Extraction Check
B2: EXTRACTION CHECK — SOURCE RECONCILIATION
B3: What the model pulled from the documents, and whether it ties to the source. Review before trusting the underwriting.
B5: REPORTING PERIOD USED
B6: Period used | C6: Monthly recap 11/01/24 - 10/31/25
B7: Date range | C7: Nov 2024 - Oct 2025
B8: Months covered | C8: 12
B9: Other periods seen in doc | C9: Monthly recap 11/01/24 - 10/31/25 (accrual basis), PRO FORMA
B10: Notes | C10: The document contains one T12 period (Nov 2024 - Oct 2025) with 12 monthly columns (NOV 24 through OCT 25) plus a PRO FORMA column. The T12 TOTAL column (O) is the operative annual figure. PRO FORMA is a forward-looking projection and was not used.
B12: RECONCILIATION CHECKS
B13: ⚠ 3 FAILED, 2 warnings, 63 passed — review the failures before using these numbers.
B14: Item | C14: Check | D14: Status | E14: Detail
B15: Rent roll rows vs unit count | C15: Rent roll long | D15: ✗ FAIL | E15: 127 rows but only 109 units stated — verify unit count or check for non-unit rows.
B16: POH count vs rent roll | C16: User stated 0 POH | D16: ✗ FAIL | E16: User stated 0 park-owned homes but the rent roll has home rent entries. Use the rent-roll count as authoritative — the user input was wrong.
B17: Rent-roll vs income parity: Retail/Commercial | C17: Expect non-zero 'Retail Income' income | D17: ✗ FAIL | E17: Rent roll has 2 occupied Retail/Commercial unit(s) but 'Retail Income' income totals $0. The LLM likely collapsed this revenue into another category (most often Gross Potential Rent).
B18: Multiple periods in doc | C18: Picked most recent T12 | D18: ⚠ WARN | E18: Document had 2 period columns: Monthly recap 11/01/24 - 10/31/25 (accrual basis), PRO FORMA. Confirm the right one was used.
B19: Methodology schema validation | C19: Per-line Pydantic check | D19: ⚠ WARN | E19: expenses[6]: Value error, Repair and Maintenance (5107 Septic + 5108 Plumbing + 5109 Misc + 5110 Equipment + 5111 Electrical + 5200 Park Supplies): monthly sum $9,733.42 != t12Total $10,414.78 (diff $681.36, 6.5%)
B20: Reporting period | C20: T12 (12 months) | D20: ✓ OK | E20: Monthly recap 11/01/24 - 10/31/25 (Nov 2024 - Oct 2025)
B21: Income: 4101 Lot Rent | C21: Monthlies sum to annual | D21: ✓ OK | E21: Σmonthly=1,144,604 vs annual=1,144,604
B22: Income: 4103 Long Term RV Lot Rent | C22: Monthlies sum to annual | D22: ✓ OK | E22: Σmonthly=172,705 vs annual=172,705
B23: Income: 4108 Storage Unit Rent | C23: Monthlies sum to annual | D23: ✓ OK | E23: Σmonthly=900 vs annual=900
B24: Income: 4110 Retail Unit Rent | C24: Monthlies sum to annual | D24: ✓ OK | E24: Σmonthly=12,426 vs annual=12,426
B25: Income: 4131 Move in Specials | C25: Monthlies sum to annual | D25: ✓ OK | E25: Σmonthly=-168 vs annual=-168
... B82: Expense ratio | C82: 25–55% typical for MHC, 35–50% for hybrid | D82: ✓ OK | E82: Underwritten expense ratio = 37.4%

Sheet Miscellaneous
B2: PROPERTY OVERVIEW
B3: Location context, visuals, demographics, and qualitative assessment
B5: PROPERTY LINKS
B6: Property Name | C6: Whaleshead Beach Resort
B7: Address | C7: 19921 Whaleshead Road, Brookings, OR
B8: Property Type | C8: Hybrid
B9: Total Units | C9: 109
B10: County | C10: Curry
B11: Asking Price | C11: 10000000
B12: CoStar Link
B13: Property Website
B14: Broker / OM
B15: County Assessor
B16: FEMA Flood Map
B18: DEMOGRAPHICS
B19: County Population | C19: 21776
B20: 5-Year Population Growth | C20: -4.0%
B21: Median Household Income | C21: $62,244
B22: Unemployment Rate | C22: 5.4%
B23: Top Employers | C23: Curry Health Network / Curry Medical Center (Brookings) & Curry General Hospital (Gold Beach), Brookings-Harbor School District 17C, Curry County government, City of Brookings, Port of Brookings Harbor commercial fishing fleet (crab/salmon/tuna), Fred Meyer and local retail, Sutter Coast Hospital (Crescent City, CA - regional), OSU Extension / Southwestern Oregon Community College
B25: ALTERNATIVE HOUSING (affordability)
B26: Avg Single-Family Home Price | C26: $580,000
B27: Avg 1BR Apartment Rent | C27: $900/mo
B28: Avg 2BR Apartment Rent | C28: $1,477/mo
B29: Avg 3BR Apartment Rent | C29: $1,650/mo
B30: MHP All-In Monthly Cost | C30: $1,068/mo
B31: MHP Savings vs 2BR Apt | C31: 28.0%
B33: AERIAL & LOCATION MAP
B34: Satellite / Aerial | D34: Roadmap (with landmarks)
B51: STREET VIEW
B52: Main Entrance | D52: Interior Road
B69: Example Home #1 | D69: Example Home #2
B86: CLICKABLE URLs
B87: Aerial / Satellite | C87: https://www.google.com/maps/place/19921+Whaleshead+Rd,+Brookings,+OR+97415/@42.1547,-124.3556,1000m/data=!3m1!1e3
B88: Roadmap | C88: https://www.google.com/maps/search/?api=1&query=19921+Whaleshead+Road%2C+Brookings%2C+OR
B89: Street View — Main Entrance | C89: https://www.google.com/maps?q=19921+Whaleshead+Road,+Brookings,+OR+97415&layer=c
B90: Street View — Interior Road | C90: https://www.google.com/maps/@42.1547,-124.3556,3a,75y/data=!3m6!1e1
B91: Street View — Example Home #1 | C91: https://www.google.com/maps/search/Whaleshead+Beach+Resort+Brookings+OR
B92: Street View — Example Home #2 | C92: https://www.google.com/maps/search/19921+Whaleshead+Rd+Brookings+OR+homes
B93: Driving Directions | C93: https://www.google.com/maps/dir/Brookings,+OR/19921+Whaleshead+Rd,+Brookings,+OR+97415
...

Sheet Comps Analysis
B2: COMPS ANALYSIS — DETAILED COMPETITIVE SET
B3: Rent comps, sale comps, statistics, and subject-vs-market positioning
B5: INVESTMENT CRITERIA CHECK — 200 bps spread rule
B6: Ingoing Cap Rate | C6: Stabilized Yield on Cost | D6: Spread (bps) | E6: Hurdle | F6: Verdict
B7: 0.091 | C7: 0.0966 | D7: +56 bps | E7: ≥ 200 bps | F7: ✗ DOES NOT MEET INVESTMENT CRITERIA
B8: Spread is 56 bps — 144 bps short of the 200 bps hurdle. GGC does not pay for value it's creating; this deal would require either a lower purchase price or a more aggressive stabilized plan to clear.
B11: SUBJECT vs MARKET — KEY METRICS
B12: Metric | C12: Subject | D12: Comp Min | E12: Comp Max | F12: Comp Avg | G12: Comp Median | H12: Subject Position
B13: Lot Rent ($/mo) | C13: 966.38 | D13: 575 | E13: 740 | F13: 618 | G13: 600 | H13: 56.4% above avg
B14: # Sites | C14: 109 | D14: 20 | E14: 63 | F14: 44.6 | G14: 50
B15: Occupancy | C15: 0.984 | D15: 1 | E15: 1 | F15: 1 | G15: 1
B18: RENT COMPS (16 found)
B19: Property | C19: Location | D19: Distance | E19: # Sites | F19: Lot Rent | G19: Occupancy | H19: Year Built | I19: POH % | J19: Amenities | K19: Quality | L19: Source
B20: Sunset View Mobile Home Park | C20: Brookings, OR | D20: 7.0 mi | E20: 50 | F20: 740 | G20: 1 | H20: 1974 | J20: Off-street parking, paved streets, WiFi, pet-friendly (under 20 lbs), 55+ age-re | K20: ★★★ | L20: https://www.mhvillage.com/parks/22374
B21: Tamaroo Mobile Home Park | C21: Brookings, OR | D21: 7.2 mi | F21: 600 | J21: Paved average-width streets, well water, septic, off-street parking, 55+ age-res | K21: ★★★ | L21: https://www.mhbo.com/mobile-home-park/90764-tamaroo-mobile-home-park-16329-grootendorst-street-brookings-or-97415
B22: Brookings Mobile Home Park | C22: Brookings, OR | D22: 6.5 mi | F22: 600 | J22: All-ages, pet-friendly, city water/sewer, paved streets, near Hwy 101 and Chetco | K22: ★★★ | L22: https://www.mhbo.com/mobile-home-park/88472-brookings-mobile-home-park-16391-us-101-brookings-or-97415
B23: Driftwood Estates | C23: Harbor (Brookings), OR | D23: 8.0 mi | E23: 62 | F23: 575 | J23: 55+ community, minutes from beach, near Port of Brookings Harbor | K23: ★★★ | L23: https://www.mobilehome.net/mobile-home-parks/59111-harbor-hills-mh-park-in-brookings-or
B24: Harbor Hills MH Park | C24: Brookings, OR | D24: 8.0 mi | E24: 28 | J24: Highway-frontage manufactured home community | K24: ★★ | L24: https://www.mhbo.com/mobile-home-park/76579-harbor-hills-mh-park-15765-highway-101-s-brookings-or-97415
B25: Driftwood RV Park (long-term sites) | C25: Harbor, OR | D25: 8.0 mi | F25: 575 | J25: Full hookups (water/sewer/trash/cable/electric), clubhouse/banquet room, on-site | K25: ★★★ | L25: https://www.driftwoodrvpark.com/
B26: Ocean View Mobile Estates | C26: Brookings, OR | D26: 7.0 mi | J26: Manufactured home community | L26: https://www.mobilehome.net/mobile-home-park-directory/oregon/brookings
B27: Pleasant Hill Mobile Estates | C27: Brookings, OR | D27: 7.0 mi | J27: Manufactured home community | L27: https://www.mobilehome.net/mobile-home-park-directory/oregon/brookings
B28: Vista Hills Mobile Home Park | C28: Brookings, OR | D28: 7.0 mi | J28: Manufactured home community | L28: https://www.mobilehomeparkstore.com/mobile-home-park-directory/oregon/brookings
B29: Emerald Coast Estates | C29: Brookings, OR | D29: 7.0 mi | J29: Gated premier 55+ community, newer Energy Star homes | K29: ★★★★ | L29: https://www.redfin.com/city/23199/OR/Harbor
B30: Rainbow Rock Village | C30: Brookings, OR | D30: 9.0 mi | J30: Oceanfront/north-county manufactured community | L30: https://www.mobilehomeparkstore.com/mobile-home-park-directory/oregon/brookings
B31: Tonopah Mobile Home Village | C31: Brookings, OR | D31: 7.0 mi | J31: Manufactured home community | L31: https://www.mhbay.com/mobile-home-park-directory/oregon/brookings
B32: Mountain View MH Park | C32: Brookings, OR | D32: 7.0 mi | J32: Manufactured home community | L32: https://www.mobilehomeparkstore.com/mobile-home-park-directory/oregon/brookings
B33: River Hills Estates | C33: Gold Beach, OR | D33: 21.0 mi | J33: All-age community along the Rogue River corridor | L33: https://www.mobilehome.net/mobile-home-parks/59111-harbor-hills-mh-park-in-brookings-or
B34: Rogue Pacific MHP | C34: Gold Beach, OR | D34: 21.0 mi | E34: 63 | J34: Manufactured home community near coast | L34: https://www.mobilehome.net/mobile-home-parks/59111-harbor-hills-mh-park-in-brookings-or
B35: Riverview Village MHP | C35: Gold Beach, OR | D35: 23.0 mi | E35: 20 | J35: Riverside manufactured home community | L35: https://www.mobilehome.net/mobile-home-parks/59111-harbor-hills-mh-park-in-brookings-or
B36: STATISTICS | D36: Range: | E36: 20-63 | F36: $575-$740
D37: Average: | E37: 45 | F37: $618 | G37: 100.0%
B38: MARKET RENT CONCLUSION
B39: Brookings-area lot/space rents cluster in a 450-750 monthly band, with Brookings Mobile Home Park at 450-750, Tamaroo at 475-725, and Sunset View posting an average of 740 with zero vacant sites. The subject's 109 sites sit at the larger end of a market dominated by sub-65-site parks, giving it scarcity value. Assuming the subject is currently positioned mid-band (~650), there is realistic upside of 50-100 per site toward the 740-750 ceiling already proven by occupied competitors, implying roughly 65,000-130,000 of annual revenue lift at full occupancy. Coastal demand and minimal new MHP supply support pushing rents to the top of the prevailing range over time.
B41: SALE COMPS (10 found)
B42: Property | C42: Location | D42: Sale Date | E42: # Sites | F42: Sale Price | G42: $ / Unit | H42: Cap Rate | I42: NOI | J42: Buyer | K42: Seller | L42: Source
B43: Coos Bay Mobile Home Park (12-unit) | C43: Coos Bay, OR | D43: 05/26 | E43: 12 | F43: 1600000 | G43: 133333 | L43: https://www.loopnet.com/search/mobile-home-parks/or/for-sale/
B44: Lebanon Mobile Home Park (36-unit) | C44: Lebanon, OR | D44: 05/26 | E44: 36 | F44: 2045000 | G44: 56806 | H44: 0.05 | I44: 102250 | L44: https://www.loopnet.com/search/mobile-home-parks/or/for-sale/
B45: Keizer Mobile Home Park (14-unit) | C45: Keizer, OR | D45: 05/26 | E45: 14 | F45: 1237000 | G45: 88357 | H45: 0.05 | I45: 61850 | L45: https://www.loopnet.com/search/mobile-home-parks/or/for-sale/
B46: Tillamook Mobile Home Park (27-unit) | C46: Tillamook, OR | D46: 05/26 | E46: 27 | F46: 2700000 | G46: 100000 | L46: https://www.loopnet.com/search/mobile-home-parks/or/for-sale/
B47: Central Point Mobile Home Park (25-unit) | C47: Central Point, OR | D47: 05/26 | E47: 25 | F47: 1995000 | G47: 79800 | L47: https://www.loopnet.com/search/mobile-home-parks/or/for-sale/
...

Sheet Data Consolidation
A1: Choose Income Category | B1: Input Source Data | D1: Input Source Data | G1: Choose Ann. # | H1: 3
A2: GGC Catorgy | B2: Source Name | D2: 2023 | E2: 2024 | F2: Broker's Proforma Y1 | G2: T12 | H2: Annualization | J2: 45444 | K2: 45474 | L2: 45505 | M2: 45536 | N2: 45566 | O2: 45597 | P2: 45627 | Q2: 45658 | R2: 45689 | S2: 45717 | T2: 45748 | U2: 45992 | V2: T12
A3: Gross Potential Rent | B3: 4101 Lot Rent | E3: 1144604.5 | F3: 1144604.5 | G3: 1144604.5 | H3: =((SUM(S3:U3)/$H$1)*12) | J3: 88056 | K3: 88063.94 | L3: 95245 | M3: 96356 | N3: 97084 | O3: 97396 | P3: 97648 | Q3: 97396.53 | R3: 96074 | S3: 97095 | T3: 97095 | U3: 97095 | V3: =SUM(J3:U3)
A4: Less: Vacancy | B4: Physical vacancy (rent roll) | E4: 0 | F4: 0 | G4: 0 | H4: =((SUM(S4:U4)/$H$1)*12) | J4: -1932.75 | K4: -1932.75 | L4: -1932.75 | M4: -1932.75 | N4: -1932.75 | O4: -1932.75 | P4: -1932.75 | Q4: -1932.75 | R4: -1932.75 | S4: -1932.75 | T4: -1932.75 | U4: -1932.75 | V4: =(((SUM(J4:U4))))
A5: Less: Concessions | B5: 4131 Move in Specials | E5: -168 | F5: -168 | G5: -168 | H5: =((SUM(S5:U5)/$H$1)*12) | J5: -84 | K5: -84 | L5: 0 | M5: 0 | N5: 0 | O5: 0 | P5: 0 | Q5: 0 | R5: 0 | S5: 0 | T5: 0 | U5: 0 | V5: =SUM(J5:U5)
A6: Less: Bad Debt | B6: 6120 Bad Debt (re-routed from expense block to income contra) | E6: -26061.7 | F6: -26061.7 | G6: -26061.7 | H6: =((SUM(S6:U6)/$H$1)*12) | J6: -35.6 | K6: -6151.01 | L6: 0 | M6: -1886.84 | N6: 0 | O6: -3846.97 | P6: -10326.98 | Q6: -3814.3 | R6: 0 | S6: 0 | T6: 0 | U6: 0 | V6: =SUM(J6:U6)
A7: RV Site Rental Income | B7: 4103 Long Term RV Lot Rent | E7: 172705.2 | F7: 172705.2 | G7: 172705.2 | H7: =((SUM(S7:U7)/$H$1)*12) | J7: 17051 | K7: 14962 | L7: 15578 | M7: 15645 | N7: 14563 | O7: 14831 | P7: 14090 | Q7: 14090 | R7: 13416 | S7: 12742 | T7: 12742 | U7: 12995.2 | V7: =SUM(J7:U7)
A8: Parking Income | B8: 4108 Storage Unit Rent | E8: 900 | F8: 900 | G8: 900 | H8: =((SUM(S8:U8)/$H$1)*12) | J8: 75 | K8: 75 | L8: 75 | M8: 75 | N8: 75 | O8: 75 | P8: 75 | Q8: 75 | R8: 75 | S8: 75 | T8: 75 | U8: 75 | V8: =SUM(J8:U8)
A9: Retail | B9: 4110 Retail Unit Rent | E9: 12425.81 | F9: 12425.81 | G9: 12425.81 | H9: =((SUM(S9:U9)/$H$1)*12) | J9: 1200 | K9: 1200 | L9: 425.81 | M9: 0 | N9: 1200 | O9: 1200 | P9: 1200 | Q9: 1200 | R9: 1200 | S9: 1200 | T9: 1200 | U9: 1200 | V9: =SUM(J9:U9)
A10: Utility Reimbursement | B10: 4403 Electric | E10: 79147.02 | F10: 79147.02 | G10: 79147.02 | H10: =((SUM(S10:U10)/$H$1)*12) | J10: 5895.17 | K10: 7136.87 | L10: 8138.93 | M10: 7443.4 | N10: 9404.69 | O10: 7438.49 | P10: 6708.47 | Q10: 6135.98 | R10: 6004.45 | S10: 5116.73 | T10: 4779.05 | U10: 4944.79 | V10: =SUM(J10:U10)
A11: Utility Reimbursement | B11: 4404 Garbage | E11: 30 | F11: 30 | G11: 30 | H11: =((SUM(S11:U11)/$H$1)*12) | J11: 0 | K11: 0 | L11: 0 | M11: 0 | N11: 0 | O11: 0 | P11: 0 | Q11: 0 | R11: 0 | S11: 0 | T11: 0 | U11: 30 | V11: =SUM(J11:U11)
A12: Other Income | B12: 4402 Water & Sewer (contra) | E12: -1709 | F12: -1709 | G12: -1709 | H12: =((SUM(S12:U12)/$H$1)*12) | J12: 0 | K12: 0 | L12: 0 | M12: -1709 | N12: 0 | O12: 0 | P12: 0 | Q12: 0 | R12: 0 | S12: 0 | T12: 0 | U12: 0 | V12: =SUM(J12:U12)
A13: Other Income | B13: 4304 Damages | E13: 1250.65 | F13: 1250.65 | G13: 1250.65 | H13: =((SUM(S13:U13)/$H$1)*12) | J13: 0 | K13: 0 | L13: 0 | M13: 0 | N13: 1250.65 | O13: 0 | P13: 0 | Q13: 0 | R13: 0 | S13: 0 | T13: 0 | U13: 0 | V13: =SUM(J13:U13)
A14: Other Income | B14: 4905 Recovered Legal/Court Fees | E14: 3183.75 | F14: 3183.75 | G14: 3183.75 | H14: =((SUM(S14:U14)/$H$1)*12) | J14: 0 | K14: 0 | L14: 0 | M14: 0 | N14: 0 | O14: 0 | P14: 1305.25 | Q14: 1878.5 | R14: 0 | S14: 0 | T14: 0 | U14: 0 | V14: =SUM(J14:U14)
A15: Other Income | B15: 4907 Violation Fines | E15: 50 | F15: 50 | G15: 50 | H15: =((SUM(S15:U15)/$H$1)*12) | J15: 0 | K15: 0 | L15: 0 | M15: 0 | N15: 0 | O15: 0 | P15: 0 | Q15: 50 | R15: 0 | S15: 25 | T15: -25 | U15: 0 | V15: =SUM(J15:U15)
A16: Other Income | B16: 4908 Payment Processing Fee | E16: 7159.9 | F16: 7159.9 | G16: 7159.9 | H16: =((SUM(S16:U16)/$H$1)*12) | J16: 630.54 | K16: 692.09 | L16: 635.06 | M16: 627.78 | N16: 666.63 | O16: 646.82 | P16: 562.24 | Q16: 572.18 | R16: 514.04 | S16: 539.64 | T16: 548.87 | U16: 524.01 | V16: =SUM(J16:U16)
... A21: Other Income | B21: 4915 NSF Fees | E21: 375 | F21: 375 | G21: 375 | H21: =((SUM(S21:U21)/$H$1)*12) | J21: 50 | K21: 0 | L21: 25 | M21: 25 | N21: 25 | O21: 75 | P21: 50 | Q21: 0 | R21: 25 | S21: 100 | T21: 0 | U21: 0 | V21: =SUM(J21:U21)
H22: =F22*4
D23: =SUM(D3:D21) | E23: =SUM(E3:E21) | F23: =SUM(F3:F21) | G23: =SUM(G3:G21) | H23: =SUM(H3:H21) | I23: =SUM(I3:I21) | J23: =SUM(J3:J21) | K23: =SUM(K3:K21) | ... V23: =SUM(V3:V21)
B24: Input Source Data
B25: Check | D25: =IF(D23=D24,"OK") | E25: =IF(E23=E24,"OK") | F25: =IF(F23=F24,"OK") | G25: =IF(G23=G24,"OK") | H25: N/A | J25: =IF(J23=J24,"OK") | K25: =IF(K23=K24,"OK") | L25: =IF(L23=L24,"OK") | M25: =IF(M23=M24,"OK") | N25: =IF(N23=N24,"OK") | O25: =IF(O23=O24,"OK") | P25: =IF(P23=P24,"OK") | Q25: =IF(Q23=Q24,"OK") | ... V25: =IF(V23=V24,"OK")
A27: Choose Expense Category | B27: Input Source Data | D27: Input Source Epense Data | H27: =H1 | J27: =J2 | K27: =K2 | L27: =L2 | M27: =M2 | N27: =N2 | O27: =O2 | P27: =P2 | Q27: =Q2 | ... U27: =U2 | V27: Total
H28: =((SUM(S28:U28)/$H$1)*12) | V28: =SUM(J28:U28)
H29: =((SUM(S29:U29)/$H$1)*12) | V29: =SUM(J29:U29)
H30: =((SUM(S30:U30)/$H$1)*12) | V30: =SUM(J30:U30)
H31: =((SUM(S31:U31)/$H$1)*12) | V31: =SUM(J31:U31)
H32: =((SUM(S32:U32)/$H$1)*12) | V32: =SUM(J32:U32)
H33: =((SUM(S33:U33)/$H$1)*12) | V33: =SUM(J33:U33)
H34: =((SUM(S34:U34)/$H$1)*12) | V34: =SUM(J34:U34)
H35: =((SUM(S35:U35)/$H$1)*12) | V35: =SUM(J35:U35)
H36: =((SUM(S36:U36)/$H$1)*12) | V36: =SUM(J36:U36)
H37: =((SUM(S37:U37)/$H$1)*12) | V37: =SUM(J37:U37)
H38: =((SUM(S38:U38)/$H$1)*12) | V38: =SUM(J38:U38)
H39: =((SUM(S39:U39)/$H$1)*12) | V39: =SUM(J39:U39)
... H42: =((SUM(S42:U42)/$H$1)*12) | V42: =SUM(J42:U42)
A43: RE Taxes | B43: 5301 Property Taxes | E43: 15390.51 | F43: 15390.51 | G43: 15390.51 | H43: =((SUM(S43:U43)/$H$1)*12) | J43: 1243.41 | K43: 1243.41 | L43: 1492.92 | M43: 1243.41 | N43: 1243.41 | O43: 1463.39 | P43: 1243.41 | Q43: 1243.43 | R43: 1243.43 | S43: 1243.43 | T43: 1243.43 | U43: 1243.43 | V43: =SUM(J43:U43)
A44: Insurance | B44: 5051 Car Insurance + 5053 Liability Insurance | E44: 37680.97 | F44: 37680.97 | G44: 37680.97 | H44: =((SUM(S44:U44)/$H$1)*12) | J44: 3230.91 | K44: 3234.24 | L44: 3224.27 | M44: 3230.91 | N44: 3368.16 | O44: 3340.71 | P44: 3340.71 | Q44: 3340.71 | R44: 2784.99 | S44: 2784.99 | T44: 2794.69 | U44: 3005.68 | V44: =SUM(J44:U44)
A45: Gas/Fuel | B45: 5401 Fuel for Vehicles + 5406 Gas & Propane | E45: 2806.94 | F45: 2806.94 | G45: 2806.94 | H45: =((SUM(S45:U45)/$H$1)*12) | J45: 0 | K45: 75.48 | L45: 185.18 | M45: 75.21 | N45: 1929.44 | O45: 108.36 | P45: 109.17 | Q45: 146.92 | R45: 139.94 | S45: 37.24 | T45: 0 | U45: 0 | V45: =SUM(J45:U45)
A46: Electrcitiy | B46: 5404 Electric | E46: 93309.56 | F46: 93309.56 | G46: 93309.56 | H46: =((SUM(S46:U46)/$H$1)*12) | J46: 6947.07 | K46: 8871.79 | L46: 8845.15 | M46: 9808.06 | N46: 9372.18 | O46: 9800.4 | P46: 7480.45 | Q46: 7135.25 | R46: 6309.76 | S46: 6385.77 | T46: 6149.59 | U46: 6204.09 | V46: =SUM(J46:U46)
A47: Water and Sewer | B47: 5402 Water & Sewer + 5403 Water Testing | E47: 57277.28 | F47: 57277.28 | G47: 57277.28 | H47: =((SUM(S47:U47)/$H$1)*12) | J47: 2605.17 | K47: 5411.91 | L47: 6936.49 | M47: 6639.17 | N47: 3819.28 | O47: 4149.08 | P47: 3844.62 | Q47: 3427.94 | R47: 5729.44 | S47: 3850.64 | T47: 4833.27 | U47: 6030.27 | V47: =SUM(J47:U47)
...

Sheet Collections
A1: GARY GROUP CAPITAL
B4: Month | C4: GPR | D4: Vacant | E4: Concessions | F4: Bad Debt | G4: Net Rental Income | H4: RUBS | I4: HR Income | J4: RV Income | K4: Parking | L4: Laundry | M4: Other Income | N4: EGI
B5: ='Data Consolidation'!J2 | C5: =SUMIFS('Data Consolidation'!J3:J21,'Data Consolidation'!$A$3:$A$21,"Gross Potential Rent") | D5: =SUMIFS('Data Consolidation'!$J$3:$J$21,'Data Consolidation'!$A$3:$A$21,"Vacancy") | E5: =SUMIFS('Data Consolidation'!$J$3:$J$21,'Data Consolidation'!$A$3:$A$21,"Concessions") | F5: =SUMIFS('Data Consolidation'!$J$3:$J$21,'Data Consolidation'!$A$3:$A$21,"bad debt") | G5: =SUM(C5:F5) | H5: =SUMIFS('Data Consolidation'!$J$3:$J$21,'Data Consolidation'!$A$3:$A$21,"Utility Reimbursement") | I5: =SUMIFS('Data Consolidation'!$J$3:$J$21,'Data Consolidation'!$A$3:$A$21,"Home Rent Income") | J5: =SUMIFS('Data Consolidation'!$J$3:$J$21,'Data Consolidation'!$A$3:$A$21,"RV site rental income") | K5: =SUMIFS('Data Consolidation'!$J$3:$J$21,'Data Consolidation'!$A$3:$A$21,"Parking Income") | L5: =SUMIFS('Data Consolidation'!$J$3:$J$21,'Data Consolidation'!$A$3:$A$21,"Laundry Income") | M5: =SUMIFS('Data Consolidation'!$J$3:$J$21,'Data Consolidation'!$A$3:$A$21,"Other Income") | N5: =G5+H5+I5+J5+K5+L5+M5
B6: ='Data Consolidation'!K2 | C6: =SUMIFS('Data Consolidation'!K$3:K$21,'Data Consolidation'!$A$3:$A$21,"Gross Potential Rent") | D6: =SUMIFS('Data Consolidation'!$K$3:$K$21,'Data Consolidation'!$A$3:$A$21,"Vacant") | E6: =SUMIFS('Data Consolidation'!$K$3:$K$21,'Data Consolidation'!$A$3:$A$21,"Concessions") | F6: =SUMIFS('Data Consolidation'!$K$3:$K$21,'Data Consolidation'!$A$3:$A$21,"bad debt") | G6: =SUM(C6:F6) | H6: =SUMIFS('Data Consolidation'!$K$3:$K$21,'Data Consolidation'!$A$3:$A$21,"Utility Reimbursement") | I6: =SUMIFS('Data Consolidation'!$K$3:$K$21,'Data Consolidation'!$A$3:$A$21,"Home Rent Income") | J6: =SUMIFS('Data Consolidation'!$K$3:$K$21,'Data Consolidation'!$A$3:$A$21,"RV site rental income") | K6: =SUMIFS('Data Consolidation'!$K$3:$K$21,'Data Consolidation'!$A$3:$A$21,"Parking Income") | L6: =SUMIFS('Data Consolidation'!$K$3:$K$21,'Data Consolidation'!$A$3:$A$21,"Laundry Income") | M6: =SUMIFS('Data Consolidation'!$K$3:$K$21,'Data Consolidation'!$A$3:$A$21,"Other Income") | N6: =G6+H6+I6+J6+K6+L6+M6
B7: ='Data Consolidation'!L2 | C7: =SUMIFS('Data Consolidation'!L$3:L$21,'Data Consolidation'!$A$3:$A$21,"Gross Potential Rent") | D7: =SUMIFS('Data Consolidation'!$L$3:$L$21,'Data Consolidation'!$A$3:$A$21,"Vacancy") | E7: =SUMIFS('Data Consolidation'!$L$3:$L$21,'Data Consolidation'!$A$3:$A$21,"Concessions") | F7: =SUMIFS('Data Consolidation'!$L$3:$L$21,'Data Consolidation'!$A$3:$A$21,"bad debt") | G7: =SUM(C7:F7) | H7: =SUMIFS('Data Consolidation'!$L$3:$L$21,'Data Consolidation'!$A$3:$A$21,"Utility Reimbursement") | I7: =SUMIFS('Data Consolidation'!$L$3:$L$21,'Data Consolidation'!$A$3:$A$21,"Home Rent Income") | J7: =SUMIFS('Data Consolidation'!$L$3:$L$21,'Data Consolidation'!$A$3:$A$21,"RV site rental income") | K7: =SUMIFS('Data Consolidation'!$L$3:$L$21,'Data Consolidation'!$A$3:$A$21,"Parking Income") | L7: =SUMIFS('Data Consolidation'!$L$3:$L$21,'Data Consolidation'!$A$3:$A$21,"Laundry Income") | M7: =SUMIFS('Data Consolidation'!$L$3:$L$21,'Data Consolidation'!$A$3:$A$21,"Other Income") | N7: =G7+H7+I7+J7+K7+L7+M7
B8: ='Data Consolidation'!M2 | C8: =SUMIFS('Data Consolidation'!M$3:M$21,'Data Consolidation'!$A$3:$A$21,"Gross Potential Rent") | D8: =SUMIFS('Data Consolidation'!$M$3:$M$21,'Data Consolidation'!$A$3:$A$21,"Vacancy") | E8: =SUMIFS('Data Consolidation'!$M$3:$M$21,'Data Consolidation'!$A$3:$A$21,"Concessions") | F8: =SUMIFS('Data Consolidation'!$M$3:$M$21,'Data Consolidation'!$A$3:$A$21,"bad debt") | G8: =SUM(C8:F8) | H8: =SUMIFS('Data Consolidation'!$M$3:$M$21,'Data Consolidation'!$A$3:$A$21,"Utility Reimbursement") | I8: =SUMIFS('Data Consolidation'!$M$3:$M$21,'Data Consolidation'!$A$3:$A$21,"Home Rent Income") | J8: =SUMIFS('Data Consolidation'!$M$3:$M$21,'Data Consolidation'!$A$3:$A$21,"RV site rental income") | K8: =SUMIFS('Data Consolidation'!$M$3:$M$21,'Data Consolidation'!$A$3:$A$21,"Parking Income") | L8: =SUMIFS('Data Consolidation'!$M$3:$M$21,'Data Consolidation'!$A$3:$A$21,"Laundry Income") | M8: =SUMIFS('Data Consolidation'!$M$3:$M$21,'Data Consolidation'!$A$3:$A$21,"Other Income") | N8: =G8+H8+I8+J8+K8+L8+M8
B9: ='Data Consolidation'!N2 | C9: =SUMIFS('Data Consolidation'!N$3:N$21,'Data Consolidation'!$A$3:$A$21,"Gross Potential Rent") | D9: =SUMIFS('Data Consolidation'!$N$3:$N$21,'Data Consolidation'!$A$3:$A$21,"Vacancy") | E9: =SUMIFS('Data Consolidation'!$N$3:$N$21,'Data Consolidation'!$A$3:$A$21,"Concessions") | F9: =SUMIFS('Data Consolidation'!$N$3:$N$21,'Data Consolidation'!$A$3:$A$21,"bad debt") | G9: =SUM(C9:F9) | H9: =SUMIFS('Data Consolidation'!$N$3:$N$21,'Data Consolidation'!$A$3:$A$21,"Utility Reimbursement") | I9: =SUMIFS('Data Consolidation'!$N$3:$N$21,'Data Consolidation'!$A$3:$A$21,"Home Rent Income") | J9: =SUMIFS('Data Consolidation'!$N$3:$N$21,'Data Consolidation'!$A$3:$A$21,"RV site rental income") | K9: =SUMIFS('Data Consolidation'!$N$3:$N$21,'Data Consolidation'!$A$3:$A$21,"Parking Income") | L9: =SUMIFS('Data Consolidation'!$N$3:$N$21,'Data Consolidation'!$A$3:$A$21,"Laundry Income") | M9: =SUMIFS('Data Consolidation'!$N$3:$N$21,'Data Consolidation'!$A$3:$A$21,"Other Income") | N9: =G9+H9+I9+J9+K9+L9+M9
B10: ='Data Consolidation'!O2 | C10: =SUMIFS('Data Consolidation'!O$3:O$21,'Data Consolidation'!$A$3:$A$21,"Gross Potential Rent") | D10: =SUMIFS('Data Consolidation'!$O$3:$O$21,'Data Consolidation'!$A$3:$A$21,"Vacancy") | E10: =SUMIFS('Data Consolidation'!$O$3:$O$21,'Data Consolidation'!$A$3:$A$21,"Concessions") | F10: =SUMIFS('Data Consolidation'!$O$3:$O$21,'Data Consolidation'!$A$3:$A$21,"bad debt") | G10: =SUM(C10:F10) | H10: =SUMIFS('Data Consolidation'!$O$3:$O$21,'Data Consolidation'!$A$3:$A$21,"Utility Reimbursement") | I10: =SUMIFS('Data Consolidation'!$O$3:$O$21,'Data Consolidation'!$A$3:$A$21,"Home Rent Income") | J10: =SUMIFS('Data Consolidation'!$O$3:$O$21,'Data Consolidation'!$A$3:$A$21,"RV site rental income") | K10: =SUMIFS('Data Consolidation'!$O$3:$O$21,'Data Consolidation'!$A$3:$A$21,"Parking Income") | L10: =SUMIFS('Data Consolidation'!$O$3:$O$21,'Data Consolidation'!$A$3:$A$21,"Laundry Income") | M10: =SUMIFS('Data Consolidation'!$O$3:$O$21,'Data Consolidation'!$A$3:$A$21,"Other Income") | N10: =G10+H10+I10+J10+K10+L10+M10
B11: ='Data Consolidation'!P2 | C11: =SUMIFS('Data Consolidation'!P$3:P$21,'Data Consolidation'!$A$3:$A$21,"Gross Potential Rent") | D11: =SUMIFS('Data Consolidation'!$P$3:$P$21,'Data Consolidation'!$A$3:$A$21,"Vacancy") | E11: =SUMIFS('Data Consolidation'!$P$3:$P$21,'Data Consolidation'!$A$3:$A$21,"Concessions") | F11: =SUMIFS('Data Consolidation'!$P$3:$P$21,'Data Consolidation'!$A$3:$A$21,"bad debt") | G11: =SUM(C11:F11) | H11: =SUMIFS('Data Consolidation'!$P$3:$P$21,'Data Consolidation'!$A$3:$A$21,"Utility Reimbursement") | I11: =SUMIFS('Data Consolidation'!$P$3:$P$21,'Data Consolidation'!$A$3:$A$21,"Home Rent Income") | J11: =SUMIFS('Data Consolidation'!$P$3:$P$21,'Data Consolidation'!$A$3:$A$21,"RV site rental income") | K11: =SUMIFS('Data Consolidation'!$P$3:$P$21,'Data Consolidation'!$A$3:$A$21,"Parking Income") | L11: =SUMIFS('Data Consolidation'!$P$3:$P$21,'Data Consolidation'!$A$3:$A$21,"Laundry Income") | M11: =SUMIFS('Data Consolidation'!$P$3:$P$21,'Data Consolidation'!$A$3:$A$21,"Other Income") | N11: =G11+H11+I11+J11+K11+L11+M11
B12: ='Data Consolidation'!Q2 | C12: =SUMIFS('Data Consolidation'!Q$3:Q$21,'Data Consolidation'!$A$3:$A$21,"Gross Potential Rent") | D12: =SUMIFS('Data Consolidation'!$Q$3:$Q$21,'Data Consolidation'!$A$3:$A$21,"Vacancy") | E12: =SUMIFS('Data Consolidation'!$Q$3:$Q$21,'Data Consolidation'!$A$3:$A$21,"Concessions") | F12: =SUMIFS('Data Consolidation'!$Q$3:$Q$21,'Data Consolidation'!$A$3:$A$21,"bad debt") | G12: =SUM(C12:F12) | H12: =SUMIFS('Data Consolidation'!$Q$3:$Q$21,'Data Consolidation'!$A$3:$A$21,"Utility Reimbursement") | I12: =SUMIFS('Data Consolidation'!$Q$3:$Q$21,'Data Consolidation'!$A$3:$A$21,"Home Rent Income") | J12: =SUMIFS('Data Consolidation'!$Q$3:$Q$21,'Data Consolidation'!$A$3:$A$21,"RV site rental income") | K12: =SUMIFS('Data Consolidation'!$Q$3:$Q$21,'Data Consolidation'!$A$3:$A$21,"Parking Income") | L12: =SUMIFS('Data Consolidation'!$Q$3:$Q$21,'Data Consolidation'!$A$3:$A$21,"Laundry Income") | M12: =SUMIFS('Data Consolidation'!$Q$3:$Q$21,'Data Consolidation'!$A$3:$A$21,"Other Income") | N12: =G12+H12+I12+J12+K12+L12+M12
B13: ='Data Consolidation'!R2 | C13: =SUMIFS('Data Consolidation'!R$3:R$21,'Data Consolidation'!$A$3:$A$21,"Gross Potential Rent") | D13: =SUMIFS('Data Consolidation'!$R$3:$R$21,'Data Consolidation'!$A$3:$A$21,"Vacancy") | E13: =SUMIFS('Data Consolidation'!$R$3:$R$21,'Data Consolidation'!$A$3:$A$21,"Concessions") | F13: =SUMIFS('Data Consolidation'!$R$3:$R$21,'Data Consolidation'!$A$3:$A$21,"bad debt") | G13: =SUM(C13:F13) | H13: =SUMIFS('Data Consolidation'!$R$3:$R$21,'Data Consolidation'!$A$3:$A$21,"Utility Reimbursement") | I13: =SUMIFS('Data Consolidation'!$R$3:$R$21,'Data Consolidation'!$A$3:$A$21,"Home Rent Income") | J13: =SUMIFS('Data Consolidation'!$R$3:$R$21,'Data Consolidation'!$A$3:$A$21,"RV site rental income") | K13: =SUMIFS('Data Consolidation'!$R$3:$R$21,'Data Consolidation'!$A$3:$A$21,"Parking Income") | L13: =SUMIFS('Data Consolidation'!$R$3:$R$21,'Data Consolidation'!$A$3:$A$21,"Laundry Income") | M13: =SUMIFS('Data Consolidation'!$R$3:$R$21,'Data Consolidation'!$A$3:$A$21,"Other Income") | N13: =G13+H13+I13+J13+K13+L13+M13
B14: ='Data Consolidation'!S2 | C14: =SUMIFS('Data Consolidation'!S$3:S$21,'Data Consolidation'!$A$3:$A$21,"Gross Potential Rent") | D14: =SUMIFS('Data Consolidation'!$S$3:$S$21,'Data Consolidation'!$A$3:$A$21,"Vacancy") | E14: =SUMIFS('Data Consolidation'!$S$3:$S$21,'Data Consolidation'!$A$3:$A$21,"Concessions") | F14: =SUMIFS('Data Consolidation'!$S$3:$S$21,'Data Consolidation'!$A$3:$A$21,"bad debt") | G14: =SUM(C14:F14) | H14: =SUMIFS('Data Consolidation'!$S$3:$S$21,'Data Consolidation'!$A$3:$A$21,"Utility Reimbursement") | I14: =SUMIFS('Data Consolidation'!$S$3:$S$21,'Data Consolidation'!$A$3:$A$21,"Home Rent Income") | J14: =SUMIFS('Data Consolidation'!$S$3:$S$21,'Data Consolidation'!$A$3:$A$21,"RV site rental income") | K14: =SUMIFS('Data Consolidation'!$S$3:$S$21,'Data Consolidation'!$A$3:$A$21,"Parking Income") | L14: =SUMIFS('Data Consolidation'!$S$3:$S$21,'Data Consolidation'!$A$3:$A$21,"Laundry Income") | M14: =SUMIFS('Data Consolidation'!$S$3:$S$21,'Data Consolidation'!$A$3:$A$21,"Other Income") | N14: =G14+H14+I14+J14+K14+L14+M14
B15: ='Data Consolidation'!T2 | C15: =SUMIFS('Data Consolidation'!T$3:T$21,'Data Consolidation'!$A$3:$A$21,"Gross Potential Rent") | D15: =SUMIFS('Data Consolidation'!$T$3:$T$21,'Data Consolidation'!$A$3:$A$21,"Vacancy") | E15: =SUMIFS('Data Consolidation'!$T$3:$T$21,'Data Consolidation'!$A$3:$A$21,"Concessions") | F15: =SUMIFS('Data Consolidation'!$T$3:$T$21,'Data Consolidation'!$A$3:$A$21,"bad debt") | G15: =SUM(C15:F15) | H15: =SUMIFS('Data Consolidation'!$T$3:$T$21,'Data Consolidation'!$A$3:$A$21,"Utility Reimbursement") | I15: =SUMIFS('Data Consolidation'!$T$3:$T$21,'Data Consolidation'!$A$3:$A$21,"Home Rent Income") | J15: =SUMIFS('Data Consolidation'!$T$3:$T$21,'Data Consolidation'!$A$3:$A$21,"RV site rental income") | K15: =SUMIFS('Data Consolidation'!$T$3:$T$21,'Data Consolidation'!$A$3:$A$21,"Parking Income") | L15: =SUMIFS('Data Consolidation'!$T$3:$T$21,'Data Consolidation'!$A$3:$A$21,"Laundry Income") | M15: =SUMIFS('Data Consolidation'!$T$3:$T$21,'Data Consolidation'!$A$3:$A$21,"Other Income") | N15: =G15+H15+I15+J15+K15+L15+M15
B16: ='Data Consolidation'!U2 | C16: =SUMIFS('Data Consolidation'!U$3:U$21,'Data Consolidation'!$A$3:$A$21,"Gross Potential Rent") | D16: =SUMIFS('Data Consolidation'!$U$3:$U$21,'Data Consolidation'!$A$3:$A$21,"Vacancy") | E16: =SUMIFS('Data Consolidation'!$U$3:$U$21,'Data Consolidation'!$A$3:$A$21,"Concessions") | F16: =SUMIFS('Data Consolidation'!$U$3:$U$21,'Data Consolidation'!$A$3:$A$21,"bad debt") | G16: =SUM(C16:F16) | H16: =SUMIFS('Data Consolidation'!$U$3:$U$21,'Data Consolidation'!$A$3:$A$21,"Utility Reimbursement") | I16: =SUMIFS('Data Consolidation'!$U$3:$U$21,'Data Consolidation'!$A$3:$A$21,"Home Rent Income") | J16: =SUMIFS('Data Consolidation'!$U$3:$U$21,'Data Consolidation'!$A$3:$A$21,"RV site rental income") | K16: =SUMIFS('Data Consolidation'!$U$3:$U$21,'Data Consolidation'!$A$3:$A$21,"Parking Income") | L16: =SUMIFS('Data Consolidation'!$U$3:$U$21,'Data Consolidation'!$A$3:$A$21,"Laundry Income") | M16: =SUMIFS('Data Consolidation'!$U$3:$U$21,'Data Consolidation'!$A$3:$A$21,"Other Income") | N16: =G16+H16+I16+J16+K16+L16+M16
B20: Avg NRI Analysis | D20: % Difference | F20: Net Rental Income
B21: T1 | C21: =G16 | D21: =(C21-C22)/C22 | E21: T1vsT3
B22: T3 | C22: =AVERAGE(G14:G16) | D22: =(C22-C23)/C23 | E22: T3vsT6
B23: T6 | C23: =AVERAGE(G11:G16) | D23: =(C23-C24)/C24 | E23: T6vsT12
B24: T12 | C24: =AVERAGE(G5:G16)
F40: EGI

Sheet Rent Roll Input
A1: RENT ROLL April 2026 | E1: MHC Only | I1: Apartments | N1: Other Income | Q1: Commercial Leases
A2: Count | B2: Unit | C2: Unit Type | D2: Occupied or Vacant | F2: Name | G2: Type detail | H2: Type code | I2: Lot Rent | J2: Home Rent | K2: Combined | M2: Combined | N2: Storage | O2: Utility RUBS | P2: Pet Income | Q2: Lease Amount | R2: Maturity | S2: Lease Type | T2: CAM Amount
A3: =IF(C3="","",ROW()-2) | C3: TOH MH Site | D3: Occupied | F3: Individual tenants (names not provided in extraction) 1 | I3: 966.38 | J3: 0 | K3: =IFERROR(I3+J3,0) | M3: =K3+L3+I3
A4: =IF(C4="","",ROW()-2) | C4: TOH MH Site | D4: Occupied | F4: Individual tenants (names not provided in extraction) 2 | I4: 966.38 | J4: 0 | K4: =IFERROR(I4+J4,0) | M4: =K4+L4+I4
A5: =IF(C5="","",ROW()-2) | C5: TOH MH Site | D5: Occupied | F5: Individual tenants (names not provided in extraction) 3 | I5: 966.38 | J5: 0 | K5: =IFERROR(I5+J5,0) | M5: =K5+L5+I5
A6: =IF(C6="","",ROW()-2) | C6: TOH MH Site | D6: Occupied | F6: Individual tenants (names not provided in extraction) 4 | I6: 966.38 | J6: 0 | K6: =IFERROR(I6+J6,0) | M6: =K6+L6+I6
A7: =IF(C7="","",ROW()-2) | C7: TOH MH Site | D7: Occupied | F7: Individual tenants (names not provided in extraction) 5 | I7: 966.38 | J7: 0 | K7: =IFERROR(I7+J7,0) | M7: =K7+L7+I7
A8: =IF(C8="","",ROW()-2) | C8: TOH MH Site | D8: Occupied | F8: Individual tenants (names not provided in extraction) 6 | I8: 966.38 | J8: 0 | K8: =IFERROR(I8+J8,0) | M8: =K8+L8+I8
A9: =IF(C9="","",ROW()-2) | C9: TOH MH Site | D9: Occupied | F9: Individual tenants (names not provided in extraction) 7 | I9: 966.38 | J9: 0 | K9: =IFERROR(I9+J9,0) | M9: =K9+L9+I9
A10: =IF(C10="","",ROW()-2) | C10: TOH MH Site | D10: Occupied | F10: Individual tenants (names not provided in extraction) 8 | I10: 966.38 | J10: 0 | K10: =IFERROR(I10+J10,0) | M10: =K10+L10+I10
A11: =IF(C11="","",ROW()-2) | C11: TOH MH Site | D11: Occupied | F11: Individual tenants (names not provided in extraction) 9 | I11: 966.38 | J11: 0 | K11: =IFERROR(I11+J11,0) | M11: =K11+L11+I11
A12: =IF(C12="","",ROW()-2) | C12: TOH MH Site | D12: Occupied | F12: Individual tenants (names not provided in extraction) 10 | I12: 966.38 | J12: 0 | K12: =IFERROR(I12+J12,0) | M12: =K12+L12+I12
A13: =IF(C13="","",ROW()-2) | C13: TOH MH Site | D13: Occupied | F13: Individual tenants (names not provided in extraction) 11 | I13: 966.38 | J13: 0 | K13: =IFERROR(I13+J13,0) | M13: =K13+L13+I13
A14: =IF(C14="","",ROW()-2) | C14: TOH MH Site | D14: Occupied | F14: Individual tenants (names not provided in extraction) 12 | I14: 966.38 | J14: 0 | K14: =IFERROR(I14+J14,0) | M14: =K14+L14+I14
... A72: =IF(C72="","",ROW()-2) | C72: TOH MH Site | D72: Occupied | F72: Individual tenants (names not provided in extraction) 70 | I72: 966.38 | J72: 0 | K72: =IFERROR(I72+J72,0) | M72: =K72+L72+I72
A73: =IF(C73="","",ROW()-2) | C73: TOH MH Site | D73: Occupied | F73: Individual tenants (names not provided in extraction) 71 | I73: 966.38 | J73: 0 | K73: =IFERROR(I73+J73,0) | O73: =SUM(O3:O72) | P73: =SUM(P3:P72) | Q73: =SUM(Q3:Q72) | R73: N/A | S73: N/A | T73: =SUM(T3:T72)
A74: =IF(C74="","",ROW()-2) | C74: TOH MH Site | D74: Occupied | F74: Individual tenants (names not provided in extraction) 72 | I74: 966.38 | J74: 0 | K74: =IFERROR(I74+J74,0)
A75: =IF(C75="","",ROW()-2) | C75: TOH MH Site | D75: Occupied | F75: Individual tenants (names not provided in extraction) 73 | I75: 966.38 | J75: 0 | K75: =IFERROR(I75+J75,0) | O75: =O73*12
A76: =IF(C76="","",ROW()-2) | C76: TOH MH Site | D76: Occupied | F76: Individual tenants (names not provided in extraction) 74 | I76: 966.38 | J76: 0 | K76: =IFERROR(I76+J76,0)
A77: =IF(C77="","",ROW()-2) | C77: TOH MH Site | D77: Occupied | F77: Individual tenants (names not provided in extraction) 75 | I77: 966.38 | J77: 0 | K77: =IFERROR(I77+J77,0)
A78: =IF(C78="","",ROW()-2) | C78: TOH MH Site | D78: Occupied | F78: Individual tenants (names not provided in extraction) 76 | I78: 966.38 | J78: 0 | K78: =IFERROR(I78+J78,0)
A79: =IF(C79="","",ROW()-2) | C79: TOH MH Site | D79: Occupied | F79: Individual tenants (names not provided in extraction) 77 | I79: 966.38 | J79: 0 | K79: =IFERROR(I79+J79,0)
A80: =IF(C80="","",ROW()-2) | C80: TOH MH Site | D80: Occupied | F80: Individual tenants (names not provided in extraction) 78 | I80: 966.38 | J80: 0 | K80: =IFERROR(I80+J80,0)
A81: =IF(C81="","",ROW()-2) | C81: TOH MH Site | D81: Occupied | F81: Individual tenants (names not provided in extraction) 79 | I81: 966.38 | J81: 0 | K81: =IFERROR(I81+J81,0)
A82: =IF(C82="","",ROW()-2) | C82: TOH MH Site | D82: Occupied | F82: Individual tenants (names not provided in extraction) 80 | I82: 966.38 | J82: 0 | K82: =IFERROR(I82+J82,0)
A83: =IF(C83="","",ROW()-2) | C83: TOH MH Site | D83: Occupied | F83: Individual tenants (names not provided in extraction) 81 | I83: 966.38 | J83: 0 | K83: =IFERROR(I83+J83,0)
A84: =IF(C84="","",ROW()-2) | C84: TOH MH Site | D84: Occupied | F84: Individual tenants (names not provided in extraction) 82 | I84: 966.38 | J84: 0 | K84: =IFERROR(I84+J84,0)
A85: =IF(C85="","",ROW()-2) | C85: TOH MH Site | D85: Occupied | F85: Individual tenants (names not provided in extraction) 83 | I85: 966.38 | J85: 0 | K85: =IFERROR(I85+J85,0)
A86: =IF(C86="","",ROW()-2) | C86: TOH MH Site | D86: Occupied | F86: Individual tenants (names not provided in extraction) 84 | I86: 966.38 | J86: 0 | K86: =IFERROR(I86+J86,0)
A87: =IF(C87="","",ROW()-2) | C87: TOH MH Site | D87: Occupied | F87: Individual tenants (names not provided in extraction) 85 | I87: 966.38 | J87: 0 | K87: =IFERROR(I87+J87,0)
... A107: =IF(C107="","",ROW()-2) | C107: TOH MH Site | D107: Occupied | F107: Individual tenants (names not provided in extraction) 105 | I107: 966.38 | J107: 0 | K107: =IFERROR(I107+J107,0)
A108: =IF(C108="","",ROW()-2) | C108: TOH MH Site | D108: Vacant | I108: 0 | J108: 0 | K108: =IFERROR(I108+J108,0)
A109: =IF(C109="","",ROW()-2) | C109: TOH MH Site | D109: Vacant | I109: 0 | J109: 0 | K109: =IFERROR(I109+J109,0)
A110: =IF(C110="","",ROW()-2) | C110: Long term RV Site | D110: Occupied | F110: Long-term RV tenants 108 | I110: 738.83 | J110: 0 | K110: =IFERROR(I110+J110,0)
A111: =IF(C111="","",ROW()-2) | C111: Long term RV Site | D111: Occupied | F111: Long-term RV tenants 109 | I111: 738.83 | J111: 0 | K111: =IFERROR(I111+J111,0)
A112: =IF(C112="","",ROW()-2) | C112: Long term RV Site | D112: Occupied | F112: Long-term RV tenants 110 | I112: 738.83 | J112: 0 | K112: =IFERROR(I112+J112,0)
A113: =IF(C113="","",ROW()-2) | C113: Long term RV Site | D113: Occupied | F113: Long-term RV tenants 111 | I113: 738.83 | J113: 0 | K113: =IFERROR(I113+J113,0)
A114: =IF(C114="","",ROW()-2) | C114: Long term RV Site | D114: Occupied | F114: Long-term RV tenants 112 | I114: 738.83 | J114: 0 | K114: =IFERROR(I114+J114,0)
A115: =IF(C115="","",ROW()-2) | C115: Long term RV Site | D115: Occupied | F115: Long-term RV tenants 113 | I115: 738.83 | J115: 0 | K115: =IFERROR(I115+J115,0)
A116: =IF(C116="","",ROW()-2) | C116: Long term RV Site | D116: Occupied | F116: Long-term RV tenants 114 | I116: 738.83 | J116: 0 | K116: =IFERROR(I116+J116,0)
...

Sheet Unit Mix Rent Growth
A1: GARY GROUP CAPITAL - UNIT MIX GROWTH
B2: for y1 realized only increases starting May
A3: Lots only | B3: next increase in May 2026
A4: Key Assumptions | B4: Year 1 | C4: Year 2 | D4: Year 3 | E4: Year 4 | F4: Year 5 | G4: Year 6 | H4: Year 7 | I4: Year 8 | J4: Year 9 | K4: Year 10
A5: MH Lot Rent (TOH) | B5: 0.035 | C5: 0.075 | D5: 0.07 | E5: 0.05 | F5: 0.04 | G5: 0.04 | H5: 0.04 | I5: 0.04 | J5: 0.04 | K5: 0.04
A6: Long Term RV Rent | B6: 0.063 | C6: 0.075 | D6: 0.07 | E6: 0.05 | F6: 0.04 | G6: 0.04 | H6: 0.04 | I6: 0.04 | J6: 0.04 | K6: 0.04
B7: 0.042 | C7: 0.075 | D7: 0.07 | E7: 0.05 | F7: 0.04 | G7: 0.04 | H7: 0.04 | I7: 0.04 | J7: 0.04 | K7: 0.04
B8: 0.035 | C8: 0.075 | D8: 0.07 | E8: 0.05 | F8: 0.04 | G8: 0.04 | H8: 0.04 | I8: 0.04 | J8: 0.04 | K8: 0.04
B10: =IFERROR(D10/$D$12,0) | C10: ='Unit Mix Summary'!B4 | D10: ='Unit Mix Summary'!E4 | E10: =IFERROR('Unit Mix Summary'!H4/'Unit Mix Summary'!E4,0) | F10: =E10*(100%+B$5) | G10: =F10*(100%+C$5) | H10: =G10*(100%+D$5) | I10: =H10*(100%+E$5) | J10: =I10*(100%+F$5) | K10: =J10*(100%+G$5)
B11: =IFERROR(D11/$D$12,0) | C11: ='Unit Mix Summary'!B5 | D11: ='Unit Mix Summary'!E5 | E11: =IFERROR('Unit Mix Summary'!H5/'Unit Mix Summary'!E5,0) | F11: =E11*(100%+B$6) | G11: =F11*(100%+C$6) | H11: =G11*(100%+D$6) | I11: =H11*(100%+E$6) | J11: =I11*(100%+F$6) | K11: =J11*(100%+G$6)
B12: =SUM(B10:B11) | C12: Total Weighted Average | D12: =SUM(D10:D11) | E12: =SUMPRODUCT($B$10:$B$11,E10:E11) | F12: =SUMPRODUCT($B$10:$B$11,F10:F11) | G12: =SUMPRODUCT($B$10:$B$11,G10:G11) | H12: =SUMPRODUCT($B$10:$B$11,H10:H11) | I12: =SUMPRODUCT($B$10:$B$11,I10:I11) | J12: =SUMPRODUCT($B$10:$B$11,J10:J11) | K12: =SUMPRODUCT($B$10:$B$11,K10:K11)
D13: $change | F13: =F12-E12 | G13: =G12-F12 | H13: =H12-G12 | I13: =I12-H12 | J13: =J12-I12 | K13: =K12-J12 | M13: Year 8 | N13: Year 9 | O13: Year 10
D14: GPR | E14: =E12*$D$12*12 | F14: =F12*$D$12*12 | G14: =G12*$D$12*12 | H14: =H12*$D$12*12 | I14: =I12*$D$12*12 | J14: =J12*$D$12*12 | K14: =K12*$D$12*12 | M14: =L14*(100%+I$5) | N14: =M14*(100%+J$5) | O14: =N14*(100%+K$5)
C15: 0 | D15: Vacant Lots | E15: ='Unit Mix Summary'!D4 | F15: =E15-C15 | M15: =L15*(100%+I$6) | N15: =M15*(100%+J$6) | O15: =N15*(100%+K$6)
C16: 0 | D16: Vacant Homes | E16: ='Unit Mix Summary'!D5 | F16: =E16-$C$16 | M16: =L16*(100%+I$7) | N16: =M16*(100%+J$7) | O16: =N16*(100%+K$7)
D17: Vacancy | E17: =SUM(E15:E16)/$D$12 | F17: =SUM(F15:F16)/$D$12 | G17: =SUM(G15:G16)/$D$12 | H17: =SUM(H15:H16)/$D$12 | I17: =SUM(I15:I16)/$D$12 | J17: =SUM(J15:J16)/$D$12 | K17: =SUM(K15:K16)/$D$12 | M17: =L17*(100%+I$8) | N17: =M17*(100%+J$8) | O17: =N17*(100%+K$8)
M18: =L18*(100%+I$9) | N18: =M18*(100%+J$9) | O18: =N18*(100%+K$9)
M19: =L19*(100%+I$10) | N19: =M19*(100%+J$10) | O19: =N19*(100%+K$10)
M20: 0 | N20: 0 | O20: 0
M21: =M16-L16 | N21: =N16-M16 | O21: =O16-N16
M22: =(J14*(1+G$5)*(1+H$5)*C14+J15*(1+G$6)*(1+H$6)*C15)*12 | N22: =(J14*(1+G$5)*(1+H$5)*(1+I$5)*C14+J15*(1+G$6)*(1+H$6)*(1+I$6)*C15)*12 | O22: =(J14*(1+G$5)*(1+H$5)*(1+I$5)*(1+J$5)*C14+J15*(1+G$6)*(1+H$6)*(1+I$6)*(1+J$6)*C15)*12
D23: Vacant Lots | E23: ='Unit Mix Summary'!D4+'Unit Mix Summary'!D5 | F23: =E23 | G23: =$F$23 | H23: =$F$23 | I23: =$F$23 | J23: =$F$23 | K23: =$F$23 | L23: =$F$23 | M23: =$F$23 | N23: =$F$23 | O23: =$F$23
D24: Vacant Homes | E24: ='Unit Mix Summary'!D6 | F24: =E24-1 | G24: =$F$24 | H24: =$F$24 | I24: =$F$24 | J24: =$F$24 | K24: =$F$24 | L24: =$F$24 | M24: =$F$24 | N24: =$F$24 | O24: =$F$24
D25: Vacancy | E25: =SUM(E23:E24)/$D$20 | F25: =SUM(F23:F24)/$D$20 | G25: =SUM(G23:G24)/$D$20 | H25: =SUM(H23:H24)/$D$20 | I25: =SUM(I23:I24)/$D$20 | J25: =SUM(J23:J24)/$D$20 | K25: =SUM(K23:K24)/$D$20 | L25: =SUM(L23:L24)/$D$20 | ... O25: =SUM(O23:O24)/$D$20
F26: min vacancy estimated
E27: 1 SW LTO 43 being evicted so categorized as a vacant POH
E28: lot 69 is a vacant site--home to be delivered in few weeks
E29: LOT 8 IS A HOME CURRENTLY BEING REHABBED
A34: Key Assumptions | B34: Year 1 | C34: Year 2 | D34: Year 3 | E34: Year 4 | F34: Year 5 | G34: Year 6 | H34: Year 7 | I34: Year 8 | J34: Year 9 | K34: Year 10
A35: POH Home Rents | B35: =4%*(8/12) | C35: 0.04 | D35: 0.04 | E35: 0.04 | F35: 0.04 | G35: 0.04 | H35: 0.04 | I35: 0.04 | J35: 0.04 | K35: 0.04
D37: Home Rents
C38: Unit Mix | D38: # of Units | E38: Avg Monthly Rent | F38: Year 1 | G38: Year 2 | H38: Year 3 | I38: Year 4 | J38: Year 5 | K38: Year 6 | L38: Year 7 | M38: Year 8 | N38: Year 9 | O38: Year 10
B39: assumes 2 vacant POH to be sold | C39: Occupied POH Rentals | D39: ='Unit Mix Summary'!C6+'Unit Mix Summary'!C7 | E39: ='Rent Roll Input'!F1004 | F39: =E39*(100%+B$35) | G39: =F39*(100%+C$35) | H39: =G39*(100%+D$35) | I39: =H39*(100%+E$35) | J39: =I39*(100%+F$35) | K39: =J39*(100%+G$35) | L39: =K39*(100%+H$35) | M39: =L39*(100%+I$35) | ... O39: =N39*(100%+K$35)
D40: Gross Home Rent Income | E40: =E39*$D$39*12 | F40: =F39*$D$39*12 | G40: =G39*$D$39*12 | H40: =H39*$D$39*12 | I40: =I39*$D$39*12 | J40: =J39*$D$39*12 | K40: =K39*$D$39*12 | L40: =L39*$D$39*12 | ... O40: =O39*$D$39*12
D41: Net HRI(less 5%) | E41: =E40*95% | F41: =F40*95% | G41: =G40*95% | H41: =H40*95% | I41: =I40*95% | J41: =J40*95% | K41: =K40*95% | L41: =L40*95% | ... O41: =O40*95%
C44: Conversion Model
H45: until POH% comes down to 22%
A47: Conversion | C47: These are currently 100% occupied | E47: POH Rentals%
A48: sell existing POH | E48: ='Unit Mix Summary'!C20 | F48: =F50/'Unit Mix Summary'!$E$12 | G48: =G50/'Unit Mix Summary'!$E$12 | H48: =H50/'Unit Mix Summary'!$E$12 | I48: =I50/'Unit Mix Summary'!$E$12 | J48: =J50/'Unit Mix Summary'!$E$12 | K48: =K50/'Unit Mix Summary'!$E$12 | L48: =L50/'Unit Mix Summary'!$E$12 | M48: =M50/'Unit Mix Summary'!$E$12 | ... O48: =O50/'Unit Mix Summary'!$E$12
E49: Current POH Rentals | F49: Year 1 | G49: Year 2 | H49: Year 3 | I49: Year 4 | J49: Year 5 | K49: Year 6 | L49: Year 7 | M49: Year 8 | N49: Year 9 | O49: Year 10
...

Sheet Unit Mix Summary
B2: MH/RV Rent Roll | C2: Next Increase in MAY 1 2026--Separate increases -see RR
C3: # of Occupied Units | D3: # of Vacant Units | E3: Total Units | F3: Occupied Monthly Rent | G3: Vacant Monthly Rent | H3: Monthly Gross Potential Rent
B4: TOH MH Site | C4: =COUNTIFS('Rent Roll Input'!$D$3:$D$1002,"Occupied",'Rent Roll Input'!$C$3:$C$1002,"TOH MH Site") | D4: =COUNTIFS('Rent Roll Input'!$D$3:$D$1002,"Vacant",'Rent Roll Input'!$C$3:$C$1002,"TOH MH Site") | E4: =SUM(C4:D4) | F4: =SUMIFS('Rent Roll Input'!$I$3:$I$1002,'Rent Roll Input'!$D$3:$D$1002,"Occupied",'Rent Roll Input'!$C$3:$C$1002,"TOH MH Site") | G4: =SUMIFS('Rent Roll Input'!$I$3:$I$1002,'Rent Roll Input'!$D$3:$D$1002,"Vacant",'Rent Roll Input'!$C$3:$C$1002,"TOH MH Site") | H4: =F4+G4
B5: POH-Infilled units | C5: =COUNTIFS('Rent Roll Input'!$D$3:$D$1002,"Occupied",'Rent Roll Input'!$C$3:$C$1002,"POH-Infilled units") | D5: =COUNTIFS('Rent Roll Input'!$D$3:$D$1002,"Vacant",'Rent Roll Input'!$C$3:$C$1002,"POH-Infilled units") | E5: =SUM(C5:D5) | F5: =SUMIFS('Rent Roll Input'!$I$3:$I$1002,'Rent Roll Input'!$D$3:$D$1002,"Occupied",'Rent Roll Input'!$C$3:$C$1002,"POH-Infilled units") | G5: =SUMIFS('Rent Roll Input'!$I$3:$I$1002,'Rent Roll Input'!$D$3:$D$1002,"Vacant",'Rent Roll Input'!$C$3:$C$1002,"POH-Infilled units") | H5: =F5+G5
B6: Long term RV Site | C6: =COUNTIFS('Rent Roll Input'!$D$3:$D$1002,"Occupied",'Rent Roll Input'!$C$3:$C$1002,"Long term RV Site") | D6: =COUNTIFS('Rent Roll Input'!$D$3:$D$1002,"Vacant",'Rent Roll Input'!$C$3:$C$1002,"Long term RV Site") | E6: =SUM(C6:D6) | F6: =SUMIFS('Rent Roll Input'!$I$3:$I$1002,'Rent Roll Input'!$D$3:$D$1002,"Occupied",'Rent Roll Input'!$C$3:$C$1002,"Long term RV Site") | G6: =SUMIFS('Rent Roll Input'!$I$3:$I$1002,'Rent Roll Input'!$D$3:$D$1002,"Vacant",'Rent Roll Input'!$C$3:$C$1002,"Long term RV Site") | H6: =F6+G6
B7: Retail/Commercial | C7: =COUNTIFS('Rent Roll Input'!$D$3:$D$1002,"Occupied",'Rent Roll Input'!$C$3:$C$1002,"Retail/Commercial") | D7: =COUNTIFS('Rent Roll Input'!$D$3:$D$1002,"Vacant",'Rent Roll Input'!$C$3:$C$1002,"Retail/Commercial") | E7: =SUM(C7:D7) | F7: =SUMIFS('Rent Roll Input'!$I$3:$I$1002,'Rent Roll Input'!$D$3:$D$1002,"Occupied",'Rent Roll Input'!$C$3:$C$1002,"Retail/Commercial") | G7: =SUMIFS('Rent Roll Input'!$I$3:$I$1002,'Rent Roll Input'!$D$3:$D$1002,"Vacant",'Rent Roll Input'!$C$3:$C$1002,"Retail/Commercial") | H7: =F7+G7
B8: Total Units | C8: =SUM(C4:C7) | D8: =SUM(D4:D7) | E8: =SUM(E4:E7)
B9: Total MH Sites (TOH + POH) | C9: =SUM(C4:C5) | D9: =SUM(D4:D5) | E9: =SUM(E4:E5) | F9: =SUM(F4:F5) | G9: =SUM(G4:G5) | H9: =SUM(H4:H5)
B10: Total POH | C10: =C5 | D10: =D5 | E10: =E5
B11: Annual GPR (MH Lot Rent) | C11: =H9*12
B12: Avg MH Lot Rent | C12: =IFERROR(H4/E4,0)
B13: Occupancy % | C13: =IFERROR(C8/E8,0)
B14: POH % | C14: =IFERROR(E10/E9,0)
B15: Annual Long term RV | C15: =H6*12
B16: Long term RV avg rent | C16: =IFERROR(H6/E6,0)
B23: Annual LTO Premium | C23: =H14*12
B24: Avg Lot Rent | C24: ='Rent Roll Input'!G1004

Sheet GGC Underwriting
A1: GARY GROUP CAPITAL
D2: Months: | E2: ='Data Consolidation'!H1 | G2: ALT NOI | H2: Lot Rent only NOI | K2: Comps | L2: Comps | P2: 46108
A3: Income | B3: ='Data Consolidation'!D2 | C3: ='Data Consolidation'!E2 | D3: ='Data Consolidation'!G2 | E3: ='Data Consolidation'!H2 | F3: ='Data Consolidation'!F2 | G3: GGC ProForma | H3: GGC ProForma | I3: GGC ProForma | J3: % of GPR | K3: Expense Comp 1 | L3: Expense Comp 2 | M3: Notes
A4: Gross Potential Rent | B4: =SUMIFS('Data Consolidation'!$D$3:$D$36,'Data Consolidation'!$A$3:$A$36,"Gross Potential Rent") | C4: =SUMIFS('Data Consolidation'!$E$3:$E$36,'Data Consolidation'!$A$3:$A$36,"Gross Potential Rent") | D4: =SUMIFS('Data Consolidation'!$G$3:$G$36,'Data Consolidation'!$A$3:$A$36,"Gross Potential Rent") | E4: =SUMIFS('Data Consolidation'!$H$3:$H$36,'Data Consolidation'!$A$3:$A$36,"Gross Potential Rent") | F4: =SUMIFS('Data Consolidation'!$F$3:$F$36,'Data Consolidation'!$A$3:$A$36,"Gross Potential Rent") | G4: ='Unit Mix Rent Growth'!H14 | H4: =I4 | I4: ='Unit Mix Summary'!C11 | M4: Property Name | N4: Whaleshead Beach Resort | O4: Purchase/Offer Price | P4: 10000000 | Q4: Purchase/Offer Price | S4: Homes
A5: Less: Vacancy | B5: =SUMIFS('Data Consolidation'!$D$3:$D$36,'Data Consolidation'!$A$3:$A$36,"Vacancy") | C5: =SUMIFS('Data Consolidation'!$E$3:$E$36,'Data Consolidation'!$A$3:$A$36,"Vacancy") | D5: =SUMIFS('Data Consolidation'!$G$3:$G$36,'Data Consolidation'!$A$3:$A$36,"Vacancy") | E5: =SUMIFS('Data Consolidation'!$H$3:$H$36,'Data Consolidation'!$A$3:$A$36,"Vacancy") | F5: =SUMIFS('Data Consolidation'!$F$3:$F$36,'Data Consolidation'!$A$3:$A$36,"Vacancy") | G5: =-5%*G4 | H5: =I5 | I5: =-J5*I4 | J5: =100%-N8 | M5: Property Address | N5: 19921 Whaleshead Road | O5: Purchase Price Per Site | P5: =P4/N7 | Q5: Purchase Price Per Site | R5: =R4/P7 | S5: Utilities
A6: Less: Concessions | B6: =SUMIFS('Data Consolidation'!$D$3:$D$36,'Data Consolidation'!$A$3:$A$36,"Concessions") | C6: =SUMIFS('Data Consolidation'!$E$3:$E$36,'Data Consolidation'!$A$3:$A$36,"Concessions") | D6: =SUMIFS('Data Consolidation'!$G$3:$G$36,'Data Consolidation'!$A$3:$A$36,"Concessions") | E6: =SUMIFS('Data Consolidation'!$H$3:$H$36,'Data Consolidation'!$A$3:$A$36,"Concessions") | F6: =SUMIFS('Data Consolidation'!$F$3:$F$36,'Data Consolidation'!$A$3:$A$36,"Concessions") | G6: =-J6*$G$4 | H6: =I6 | I6: 0 | J6: =-I6/I4 | M6: Property Type | N6: Hybrid | O6: Underwritten CAP rate | P6: =I47/P4 | Q6: Underwritten CAP rate | R6: =I47/R4 | S6: Flood Zone
A7: Less: Bad Debt | B7: =SUMIFS('Data Consolidation'!$D$3:$D$36,'Data Consolidation'!$A$3:$A$36,"Bad Debt") | C7: =SUMIFS('Data Consolidation'!$E$3:$E$36,'Data Consolidation'!$A$3:$A$36,"Bad Debt") | D7: =SUMIFS('Data Consolidation'!$G$3:$G$36,'Data Consolidation'!$A$3:$A$36,"Bad Debt") | E7: =SUMIFS('Data Consolidation'!$H$3:$H$36,'Data Consolidation'!$A$3:$A$36,"Bad Debt") | F7: =SUMIFS('Data Consolidation'!$F$3:$F$36,'Data Consolidation'!$A$3:$A$36,"Bad Debt") | G7: =-J7*$G$4 | H7: =I7 | I7: =D7 | J7: 0.03 | M7: # of Units | N7: ='Unit Mix Summary'!E8 | O7: Stabilized YOC | P7: =G47/'Sources and Uses'!C18 | Q7: Stabilized YOC | R7: =G47/'Sources and Uses'!C18
M8: Rent Roll Occupancy | N8: ='Unit Mix Summary'!C13 | P8: ='Unit Mix Summary'!C18
A9: Net Rental Income | B9: =B4-B5-B6-B7 | C9: =SUM(C4:C7) | D9: =SUM(D4:D7) | E9: =SUM(E4:E7) | F9: =SUM(F4:F7) | G9: =SUM(G4:G7) | H9: =SUM(H4:H7) | I9: =SUM(I4:I7) | J9: =I9/12 | M9: Acreage | O9: Asking Price by Seller | P9: 10000000 | Q9: Asking Price by Seller
A10: YoY % Growth | C10: =(C9-B9)/B9 | D10: =(D9-C9)/C9 | E10: =(E9-D9)/D9 | J10: =I9/$N$7 | M10: County | N10: Curry | O10: Asking Price Per Site | P10: =P9/N7 | Q10: Asking Price Per Site | R10: =R9/P7
A12: Utility Reimbursement | B12: =SUMIFS('Data Consolidation'!$D$3:$D$36,'Data Consolidation'!$A$3:$A$36,"Utility Reimbursement") | C12: =SUMIFS('Data Consolidation'!$E$3:$E$36,'Data Consolidation'!$A$3:$A$36,"Utility Reimbursement") | D12: =SUMIFS('Data Consolidation'!$G$3:$G$36,'Data Consolidation'!$A$3:$A$36,"Utility Reimbursement") | E12: =SUMIFS('Data Consolidation'!$H$3:$H$36,'Data Consolidation'!$A$3:$A$36,"Utility Reimbursement") | F12: =SUMIFS('Data Consolidation'!$F$3:$F$36,'Data Consolidation'!$A$3:$A$36,"Utility Reimbursement") | G12: =I12 | H12: =I12 | I12: =D12 | J12: =I12/$N$7 | O12: Brookings Multifamily cap rate at 6%-7.5% | Q12: Cap Rate | R12: Value | S12: Value/Unit | T12: #Units
A13: Home Rent Income | B13: =SUMIFS('Data Consolidation'!$D$3:$D$36,'Data Consolidation'!$A$3:$A$36,"Home Rent Income") | C13: =SUMIFS('Data Consolidation'!$E$3:$E$36,'Data Consolidation'!$A$3:$A$36,"Home Rent Income") | D13: =SUMIFS('Data Consolidation'!$G$3:$G$36,'Data Consolidation'!$A$3:$A$36,"Home Rent Income") | E13: =SUMIFS('Data Consolidation'!$H$3:$H$36,'Data Consolidation'!$A$3:$A$36,"Home Rent Income") | F13: =SUMIFS('Data Consolidation'!$F$3:$F$36,'Data Consolidation'!$A$3:$A$36,"Home Rent Income") | G13: ='Rent Roll Input'!J151*12*95% | H13: 0 | I13: 0 | J13: =I13/$N$7 | M13: Asset | N13: NOI | O13: CAP RATE | P13: VALUE | Q13: 0 | R13: =P13/Q13 | S13: =R13/T13 | T13: 0
A14: RV Site Rental Income | B14: =SUMIFS('Data Consolidation'!$D$3:$D$36,'Data Consolidation'!$A$3:$A$36,"RV Site Rental Income") | C14: =SUMIFS('Data Consolidation'!$E$3:$E$36,'Data Consolidation'!$A$3:$A$36,"RV Site Rental Income") | D14: =SUMIFS('Data Consolidation'!$G$3:$G$36,'Data Consolidation'!$A$3:$A$36,"RV Site Rental Income") | E14: =SUMIFS('Data Consolidation'!$H$3:$H$36,'Data Consolidation'!$A$3:$A$36,"RV Site Rental Income") | F14: =SUMIFS('Data Consolidation'!$F$3:$F$36,'Data Consolidation'!$A$3:$A$36,"RV Site Rental Income") | G14: =I14 | H14: =I14 | I14: ='Unit Mix Summary'!C15*90% | J14: =I14/$N$7 | M14: Lot Rent only NOI | N14: =I47 | O14: 0.055 | P14: =N14/O14 | Q14: 0 | R14: =P14/Q14 | S14: =R14/T14 | T14: 0
A15: Storage Income | B15: =SUMIFS('Data Consolidation'!$D$3:$D$36,'Data Consolidation'!$A$3:$A$36,"Parking Income") | C15: =SUMIFS('Data Consolidation'!$E$3:$E$36,'Data Consolidation'!$A$3:$A$36,"Parking Income") | D15: =SUMIFS('Data Consolidation'!$G$3:$G$36,'Data Consolidation'!$A$3:$A$36,"Parking Income") | E15: =SUMIFS('Data Consolidation'!$H$3:$H$36,'Data Consolidation'!$A$3:$A$36,"Parking Income") | F15: =SUMIFS('Data Consolidation'!$F$3:$F$36,'Data Consolidation'!$A$3:$A$36,"Parking Income") | G15: =I15 | H15: =I15 | I15: =D15 | J15: =I15/$N$7 | M15: Home Rent only NOI | N15: =I47-H47 | O15: 0.12 | P15: =N15/O15
A16: Retail Income | B16: =SUMIFS('Data Consolidation'!$D$3:$D$36,'Data Consolidation'!$A$3:$A$36,"Laundry Income") | C16: =SUMIFS('Data Consolidation'!$E$3:$E$36,'Data Consolidation'!$A$3:$A$36,"Retail") | D16: =SUMIFS('Data Consolidation'!$G$3:$G$36,'Data Consolidation'!$A$3:$A$36,"Retail") | E16: =SUMIFS('Data Consolidation'!$H$3:$H$36,'Data Consolidation'!$A$3:$A$36,"Retail") | F16: =SUMIFS('Data Consolidation'!$F$3:$F$36,'Data Consolidation'!$A$3:$A$36,"Retail") | G16: =I16 | I16: ='Unit Mix Summary'!H7*12*98% | J16: =I16/$N$7 | M16: Total | N16: =SUM(N14:N15) | O16: =N16/P16 | P16: =SUM(P14:P15)
A17: Other Income | B17: =SUMIFS('Data Consolidation'!$D$3:$D$36,'Data Consolidation'!$A$3:$A$36,"Other Income") | C17: =SUMIFS('Data Consolidation'!$E$3:$E$36,'Data Consolidation'!$A$3:$A$36,"Other Income") | D17: =SUMIFS('Data Consolidation'!$G$3:$G$36,'Data Consolidation'!$A$3:$A$36,"Other Income") | E17: =SUMIFS('Data Consolidation'!$H$3:$H$36,'Data Consolidation'!$A$3:$A$36,"Other Income") | F17: =SUMIFS('Data Consolidation'!$F$3:$F$36,'Data Consolidation'!$A$3:$A$36,"Other Income") | G17: =I17 | H17: =I17 | I17: =AVERAGE(C17,D17) | J17: =I17/$N$7
A19: Total Effective Gross Income | B19: =B9+B12+B13+B14+B15+B16+B17 | C19: =C9+C12+C13+C14+C15+C16+C17 | D19: =D9+D12+D13+D14+D15+D16+D17 | E19: =E9+E12+E13+E14+E15+E16+E17 | F19: =F9+F12+F13+F14+F15+F16+F17 | G19: =G9+G12+G13+G14+G15+G16+G17 | H19: =H9+H12+H13+H14+H15+H16+H17 | I19: =I9+I12+I13+I14+I15+I16+I17 | J19: =I19/$N$7 | M19: per month | O19: Tax Analysis Section
A20: YoY % Growth | C20: =(C19-B19)/B19 | D20: =(D19-C19)/C19 | E20: =(E19-D19)/D19 | M20: per unit | O20: Assessed Value
A21: Expenses | B21: =B3 | C21: =C3 | D21: =D3 | E21: Annualization | F21: Broker's Proforma | G21: GGC ProForma | H21: GGC ProForma | I21: GGC ProForma | J21: Per Unit | M21: Notes | O21: Levy Rate
A22: RE Taxes | B22: =SUMIFS('Data Consolidation'!$D$43:$D$102,'Data Consolidation'!$A$43:$A$102,"RE Taxes") | C22: =SUMIFS('Data Consolidation'!$E$43:$E$102,'Data Consolidation'!$A$43:$A$102,"RE Taxes") | D22: =SUMIFS('Data Consolidation'!$G$43:$G$102,'Data Consolidation'!$A$43:$A$102,"RE Taxes") | E22: =SUMIFS('Data Consolidation'!$H$43:$H$102,'Data Consolidation'!$A$43:$A$102,"RE Taxes") | F22: =SUMIFS('Data Consolidation'!$F$43:$F$102,'Data Consolidation'!$A$43:$A$102,"RE Taxes") | G22: =I22 | H22: =I22 | I22: =J22*N7 | J22: 400 | O22: Tax | P22: =P20*P21
A23: Insurance | B23: =SUMIFS('Data Consolidation'!$D$43:$D$102,'Data Consolidation'!$A$43:$A$102,"Insurance") | C23: =SUMIFS('Data Consolidation'!$E$43:$E$102,'Data Consolidation'!$A$43:$A$102,"Insurance") | D23: =SUMIFS('Data Consolidation'!$G$43:$G$102,'Data Consolidation'!$A$43:$A$102,"Insurance") | E23: =SUMIFS('Data Consolidation'!$H$43:$H$102,'Data Consolidation'!$A$43:$A$102,"Insurance") | F23: =SUMIFS('Data Consolidation'!$F$43:$F$102,'Data Consolidation'!$A$43:$A$102,"Insurance") | G23: =I23 | H23: =I23 | I23: =D23*1.05 | J23: =I23/$N$7
A25: Gas/Fuel | B25: =SUMIFS('Data Consolidation'!$D$43:$D$102,'Data Consolidation'!$A$43:$A$102,"Gas/Fuel") | C25: =SUMIFS('Data Consolidation'!$E$43:$E$102,'Data Consolidation'!$A$43:$A$102,"Gas/Fuel") | D25: =SUMIFS('Data Consolidation'!$G$43:$G$102,'Data Consolidation'!$A$43:$A$102,"Gas/Fuel") | E25: =SUMIFS('Data Consolidation'!$H$43:$H$102,'Data Consolidation'!$A$43:$A$102,"Gas/Fuel") | F25: =SUMIFS('Data Consolidation'!$F$43:$F$102,'Data Consolidation'!$A$43:$A$102,"Gas/Fuel") | G25: =I25 | H25: =I25 | I25: =D25*1.03 | J25: =I25/$N$7
A26: Electrcitiy | B26: =SUMIFS('Data Consolidation'!$D$43:$D$102,'Data Consolidation'!$A$43:$A$102,"Electricity") | C26: =SUMIFS('Data Consolidation'!$E$43:$E$102,'Data Consolidation'!$A$43:$A$102,"Electricity") | D26: =SUMIFS('Data Consolidation'!$G$43:$G$102,'Data Consolidation'!$A$43:$A$102,"Electricity") | E26: =SUMIFS('Data Consolidation'!$H$43:$H$102,'Data Consolidation'!$A$43:$A$102,"Electricity") | F26: =SUMIFS('Data Consolidation'!$F$43:$F$102,'Data Consolidation'!$A$43:$A$102,"Electricity") | G26: =I26 | H26: =I26 | I26: =D26*1.03 | J26: =I26/$N$7
